<?xml version="1.0" ?>
<!-- =================================================================================== -->
<!-- |    This document was autogenerated by xacro from /home/rinav/ros2_ws/install/husky_description/share/husky_description/urdf/husky_ur3.urdf.xacro | -->
<!-- |    EDITING THIS FILE BY HAND IS NOT RECOMMENDED                                 | -->
<!-- =================================================================================== -->
<robot name="husky_ur3">
  <material name="dark_grey">
    <color rgba="0.2 0.2 0.2 1.0"/>
  </material>
  <material name="medium_grey">
    <color rgba="0.6 0.6 0.6 1.0"/>
  </material>
  <material name="light_grey">
    <color rgba="0.8 0.8 0.8 1.0"/>
  </material>
  <material name="yellow">
    <color rgba="0.8 0.8 0.0 1.0"/>
  </material>
  <material name="black">
    <color rgba="0.15 0.15 0.15 1.0"/>
  </material>
  <material name="white">
    <color rgba="1.0 1.0 1.0 1.0"/>
  </material>
  <material name="red">
    <color rgba="1.0 0.0 0.0 1.0"/>
  </material>
  <material name="blue">
    <color rgba="0.0 0.0 0.8 1.0"/>
  </material>
  <material name="green">
    <color rgba="0.0 0.8 0.0 1.0"/>
  </material>
  <material name="grey">
    <color rgba="0.2 0.2 0.2 1.0"/>
  </material>
  <material name="orange">
    <color rgba="1.0 0.4235294117647059 0.0392156862745098 1.0"/>
  </material>
  <material name="brown">
    <color rgba="0.8705882352941177 0.8117647058823529 0.7647058823529411 1.0"/>
  </material>
  <!-- Base link is the center of the robot's bottom plate -->
  <link name="base_link">
    <visual>
      <origin rpy="0 0 0" xyz="0 0 0"/>
      <geometry>
        <mesh filename="package://husky_description/meshes/base_link.dae"/>
      </geometry>
    </visual>
    <collision>
      <origin rpy="0 0 0" xyz="0.0 0 0.061875"/>
      <geometry>
        <box size="0.9874 0.5709 0.12375"/>
      </geometry>
    </collision>
    <collision>
      <origin rpy="0 0 0" xyz="0 0 0.17562499999999998"/>
      <geometry>
        <box size="0.7899200000000001 0.5709 0.10375"/>
      </geometry>
    </collision>
  </link>
  <!-- Base footprint is on the ground under the robot -->
  <link name="base_footprint"/>
  <joint name="base_footprint_joint" type="fixed">
    <origin rpy="0 0 0" xyz="0 0 -0.13228"/>
    <parent link="base_link"/>
    <child link="base_footprint"/>
  </joint>
  <!-- Inertial link stores the robot's inertial information -->
  <link name="inertial_link">
    <inertial>
      <mass value="46.034"/>
      <origin xyz="-0.00065 -0.085 0.062"/>
      <inertia ixx="0.6022" ixy="-0.02364" ixz="-0.1197" iyy="1.7386" iyz="-0.001544" izz="2.0296"/>
    </inertial>
  </link>
  <joint name="inertial_joint" type="fixed">
    <origin rpy="0 0 0" xyz="0 0 0"/>
    <parent link="base_link"/>
    <child link="inertial_link"/>
  </joint>
  <!-- IMU Link-->
  <!-- Can be modified with environment variables in /etc/ros/setup.bash -->
  <link name="imu_link"/>
  <joint name="imu_joint" type="fixed">
    <origin rpy="0 0 0" xyz="0 0 0"/>
    <parent link="base_link"/>
    <child link="imu_link"/>
  </joint>
  <!-- GPS Link-->
  <!-- Can be modified with environment variables in /etc/ros/setup.bash -->
  <link name="gps_link"/>
  <joint name="gps_joint" type="fixed">
    <origin rpy="0 0 0" xyz="0 0 0"/>
    <parent link="base_link"/>
    <child link="gps_link"/>
  </joint>
  <link name="front_left_wheel">
    <inertial>
      <mass value="2.637"/>
      <origin xyz="0 0 0"/>
      <inertia ixx="0.02467" ixy="0" ixz="0" iyy="0.04411" iyz="0" izz="0.02467"/>
    </inertial>
    <visual>
      <origin rpy="0 0 0" xyz="0 0 0"/>
      <geometry>
        <mesh filename="package://husky_description/meshes/wheel.dae"/>
      </geometry>
    </visual>
    <collision>
      <origin rpy="1.570795 0 0" xyz="0 0 0"/>
      <geometry>
        <cylinder length="0.1143" radius="0.1651"/>
      </geometry>
    </collision>
  </link>
  <!-- Ignition Gazebo wheel friction properties -->
  <gazebo reference="front_left_wheel">
    <mu1>1.0</mu1>
    <mu2>0.5</mu2>
    <kp>10000000.0</kp>
    <kd>1.0</kd>
    <fdir1>1 0 0</fdir1>
    <minDepth>0.001</minDepth>
    <maxVel>0.1</maxVel>
  </gazebo>
  <joint name="front_left_wheel_joint" type="continuous">
    <parent link="base_link"/>
    <child link="front_left_wheel"/>
    <origin rpy="0 0 0" xyz="0.256 0.2854 0.03282"/>
    <axis rpy="0 0 0" xyz="0 1 0"/>
  </joint>
  <link name="front_right_wheel">
    <inertial>
      <mass value="2.637"/>
      <origin xyz="0 0 0"/>
      <inertia ixx="0.02467" ixy="0" ixz="0" iyy="0.04411" iyz="0" izz="0.02467"/>
    </inertial>
    <visual>
      <origin rpy="0 0 0" xyz="0 0 0"/>
      <geometry>
        <mesh filename="package://husky_description/meshes/wheel.dae"/>
      </geometry>
    </visual>
    <collision>
      <origin rpy="1.570795 0 0" xyz="0 0 0"/>
      <geometry>
        <cylinder length="0.1143" radius="0.1651"/>
      </geometry>
    </collision>
  </link>
  <!-- Ignition Gazebo wheel friction properties -->
  <gazebo reference="front_right_wheel">
    <mu1>1.0</mu1>
    <mu2>0.5</mu2>
    <kp>10000000.0</kp>
    <kd>1.0</kd>
    <fdir1>1 0 0</fdir1>
    <minDepth>0.001</minDepth>
    <maxVel>0.1</maxVel>
  </gazebo>
  <joint name="front_right_wheel_joint" type="continuous">
    <parent link="base_link"/>
    <child link="front_right_wheel"/>
    <origin rpy="0 0 0" xyz="0.256 -0.2854 0.03282"/>
    <axis rpy="0 0 0" xyz="0 1 0"/>
  </joint>
  <link name="rear_left_wheel">
    <inertial>
      <mass value="2.637"/>
      <origin xyz="0 0 0"/>
      <inertia ixx="0.02467" ixy="0" ixz="0" iyy="0.04411" iyz="0" izz="0.02467"/>
    </inertial>
    <visual>
      <origin rpy="0 0 0" xyz="0 0 0"/>
      <geometry>
        <mesh filename="package://husky_description/meshes/wheel.dae"/>
      </geometry>
    </visual>
    <collision>
      <origin rpy="1.570795 0 0" xyz="0 0 0"/>
      <geometry>
        <cylinder length="0.1143" radius="0.1651"/>
      </geometry>
    </collision>
  </link>
  <!-- Ignition Gazebo wheel friction properties -->
  <gazebo reference="rear_left_wheel">
    <mu1>1.0</mu1>
    <mu2>0.5</mu2>
    <kp>10000000.0</kp>
    <kd>1.0</kd>
    <fdir1>1 0 0</fdir1>
    <minDepth>0.001</minDepth>
    <maxVel>0.1</maxVel>
  </gazebo>
  <joint name="rear_left_wheel_joint" type="continuous">
    <parent link="base_link"/>
    <child link="rear_left_wheel"/>
    <origin rpy="0 0 0" xyz="-0.256 0.2854 0.03282"/>
    <axis rpy="0 0 0" xyz="0 1 0"/>
  </joint>
  <link name="rear_right_wheel">
    <inertial>
      <mass value="2.637"/>
      <origin xyz="0 0 0"/>
      <inertia ixx="0.02467" ixy="0" ixz="0" iyy="0.04411" iyz="0" izz="0.02467"/>
    </inertial>
    <visual>
      <origin rpy="0 0 0" xyz="0 0 0"/>
      <geometry>
        <mesh filename="package://husky_description/meshes/wheel.dae"/>
      </geometry>
    </visual>
    <collision>
      <origin rpy="1.570795 0 0" xyz="0 0 0"/>
      <geometry>
        <cylinder length="0.1143" radius="0.1651"/>
      </geometry>
    </collision>
  </link>
  <!-- Ignition Gazebo wheel friction properties -->
  <gazebo reference="rear_right_wheel">
    <mu1>1.0</mu1>
    <mu2>0.5</mu2>
    <kp>10000000.0</kp>
    <kd>1.0</kd>
    <fdir1>1 0 0</fdir1>
    <minDepth>0.001</minDepth>
    <maxVel>0.1</maxVel>
  </gazebo>
  <joint name="rear_right_wheel_joint" type="continuous">
    <parent link="base_link"/>
    <child link="rear_right_wheel"/>
    <origin rpy="0 0 0" xyz="-0.256 -0.2854 0.03282"/>
    <axis rpy="0 0 0" xyz="0 1 0"/>
  </joint>
  <!-- Spawn Husky chassis -->
  <link name="top_chassis_link">
    <visual>
      <origin rpy="0 0 0" xyz="0 0 0"/>
      <geometry>
        <mesh filename="package://husky_description/meshes/top_chassis.dae"/>
      </geometry>
    </visual>
  </link>
  <!-- Attach chassis to the robot -->
  <joint name="top_chassis_joint" type="fixed">
    <parent link="base_link"/>
    <child link="top_chassis_link"/>
  </joint>
  <!-- Spawn user rails -->
  <link name="user_rail_link">
    <visual>
      <geometry>
        <mesh filename="package://husky_description/meshes/user_rail.dae"/>
      </geometry>
    </visual>
  </link>
  <!-- Attach user rails to base link -->
  <joint name="user_rail" type="fixed">
    <origin rpy="0 0 0" xyz="0.272 0 0.245"/>
    <parent link="base_link"/>
    <child link="user_rail_link"/>
  </joint>
  <!-- Spawn front bumper link -->
  <link name="front_bumper_link">
    <visual>
      <geometry>
        <mesh filename="package://husky_description/meshes/bumper.dae"/>
      </geometry>
    </visual>
  </link>
  <!-- Attach front bumper -->
  <joint name="front_bumper" type="fixed">
    <origin rpy="0 0 0" xyz="0.48 0 0.091"/>
    <parent link="base_link"/>
    <child link="front_bumper_link"/>
  </joint>
  <!-- Spawn rear bumper link -->
  <link name="rear_bumper_link">
    <visual>
      <geometry>
        <mesh filename="package://husky_description/meshes/bumper.dae"/>
      </geometry>
    </visual>
  </link>
  <!-- Attach rear bumper -->
  <joint name="rear_bumper" type="fixed">
    <origin rpy="0 0 3.14159" xyz="-0.48 0 0.091"/>
    <parent link="base_link"/>
    <child link="rear_bumper_link"/>
  </joint>
  <link name="top_plate_link">
    <visual>
      <origin rpy="0 0 0" xyz="0 0 0"/>
      <geometry>
        <mesh filename="package://husky_description/meshes/top_plate.dae"/>
      </geometry>
    </visual>
    <collision>
      <origin rpy="0 0 0" xyz="0 0 0"/>
      <geometry>
        <mesh filename="package://husky_description/meshes/top_plate.stl"/>
      </geometry>
    </collision>
  </link>
  <!-- Attach top plate -->
  <joint name="top_plate_joint" type="fixed">
    <parent link="base_link"/>
    <child link="top_plate_link"/>
    <origin rpy="0 0 0" xyz="0.0812 0 0.245"/>
  </joint>
  <!-- Top plate front link -->
  <joint name="top_plate_front_joint" type="fixed">
    <parent link="top_plate_link"/>
    <child link="top_plate_front_link"/>
    <origin rpy="0 0 0" xyz="0.36367 0 0.00639"/>
  </joint>
  <!-- Top plate rear link-->
  <joint name="top_plate_rear_joint" type="fixed">
    <parent link="top_plate_link"/>
    <child link="top_plate_rear_link"/>
    <origin rpy="0 0 0" xyz="-0.36633 0 0.00639"/>
  </joint>
  <link name="top_plate_front_link"/>
  <link name="top_plate_rear_link"/>
  <!-- <xacro:if value="$(arg laser_enabled)">

      <xacro:sick_lms1xx_mount prefix="base"/>

      <xacro:sick_lms1xx frame="base_laser" topic="scan" robot_namespace="$(arg robot_namespace)"/>

      <joint name="laser_mount_joint" type="fixed">
        <origin xyz="$(arg laser_xyz)" rpy="$(arg laser_rpy)" />
        <parent link="top_plate_link" />
        <child link="base_laser_mount" />
      </joint>

    </xacro:if> -->
  <!--
      top sensor arch; include this if we have realsense enabled
      keep this as a property to make it easier to add multiple conditions, should we need
      the top bar for any additional sensors in the future
    -->
  <!-- <xacro:property name="topbar_needed_realsense" value="$(arg realsense_enabled)" />
    <xacro:if value="${topbar_needed_realsense}">
      <xacro:sensor_arch prefix="" parent="top_plate_link">
        <origin xyz="-0.35 0 0.51" rpy="0 0 -3.14"/>
      </xacro:sensor_arch>
    </xacro:if> -->
  <ros2_control name="husky_hardware" type="system">
    <hardware>
      <plugin>ign_ros2_control/IgnitionSystem</plugin>
    </hardware>
    <joint name="front_left_wheel_joint">
      <command_interface name="velocity">
        <param name="min">-1</param>
        <param name="max">1</param>
      </command_interface>
      <state_interface name="position"/>
      <state_interface name="velocity"/>
    </joint>
    <joint name="rear_left_wheel_joint">
      <command_interface name="velocity">
        <param name="min">-1</param>
        <param name="max">1</param>
      </command_interface>
      <state_interface name="position"/>
      <state_interface name="velocity"/>
    </joint>
    <joint name="front_right_wheel_joint">
      <command_interface name="velocity">
        <param name="min">-1</param>
        <param name="max">1</param>
      </command_interface>
      <state_interface name="position"/>
      <state_interface name="velocity"/>
    </joint>
    <joint name="rear_right_wheel_joint">
      <command_interface name="velocity">
        <param name="min">-1</param>
        <param name="max">1</param>
      </command_interface>
      <state_interface name="position"/>
      <state_interface name="velocity"/>
    </joint>
  </ros2_control>
  <!--
    Base UR robot series xacro macro.

    NOTE this is NOT a URDF. It cannot directly be loaded by consumers
    expecting a flattened '.urdf' file. See the top-level '.xacro' for that
    (but note that .xacro must still be processed by the xacro command).

    This file models the base kinematic chain of a UR robot, which then gets
    parameterised by various configuration files to convert it into a UR3(e),
    UR5(e), UR10(e) or UR16e, etc.

    NOTE the default kinematic parameters (i.e., link lengths, frame locations,
    offsets, etc) do not correspond to any particular robot. They are defaults
    only. There WILL be non-zero offsets between the Forward Kinematics results
    in TF (i.e., robot_state_publisher) and the values reported by the Teach
    Pendant.

    For accurate (and robot-specific) transforms, the 'kinematics_parameters_file'
    parameter MUST point to a .yaml file containing the appropriate values for
    the targeted robot.

    If using the UniversalRobots/Universal_Robots_ROS_Driver, follow the steps
    described in the readme of that repository to extract the kinematic
    calibration from the controller and generate the required .yaml file.

    Main author of the migration to yaml configs Ludovic Delval.

    Contributors to previous versions (in no particular order)

     - Denis Stogl
     - Lovro Ivanov
     - Felix Messmer
     - Kelsey Hawkins
     - Wim Meeussen
     - Shaun Edwards
     - Nadia Hammoudeh Garcia
     - Dave Hershberger
     - G. vd. Hoorn
     - Philip Long
     - Dave Coleman
     - Miguel Prada
     - Mathias Luedtke
     - Marcel Schnirring
     - Felix von Drigalski
     - Felix Exner
     - Jimmy Da Silva
     - Ajit Krisshna N L
     - Muhammad Asif Rana
  -->
  <!--
    NOTE the macro defined in this file is NOT part of the public API of this
          package. Users CANNOT rely on this file being available, or stored in
          this location. Nor can they rely on the existence of the macro.
  -->
  <!-- ros_control plugin -->
  <!--gazebo>
    <plugin name="gazebo_ros_control" filename="libgazebo_ros_control.so">
      <robotNamespace>/rh_p12_rn</robotNamespace>
      <robotSimType>gazebo_ros_control/DefaultRobotHWSim</robotSimType>
      <legacyModeNS>true</legacyModeNS>
    </plugin>
  </gazebo-->
  <!-- rh_p12_rn_base -->
  <gazebo reference="rh_p12_rn_base">
    <mu1>0.2</mu1>
    <mu2>0.2</mu2>
    <material>Gazebo/DarkGrey</material>
    <minDepth>0.001</minDepth>
    <maxVel>0</maxVel>
  </gazebo>
  <!-- rh_p12_rn_r1 -->
  <gazebo reference="rh_p12_rn_r1">
    <mu1>15</mu1>
    <mu2>150</mu2>
    <material>Gazebo/DarkGrey</material>
    <minDepth>0.001</minDepth>
    <maxVel>0</maxVel>
  </gazebo>
  <!-- rh_p12_rn_r2 -->
  <gazebo reference="rh_p12_rn_r2">
    <mu1>15</mu1>
    <mu2>150</mu2>
    <material>Gazebo/DarkGrey</material>
    <minDepth>0.001</minDepth>
    <maxVel>0</maxVel>
  </gazebo>
  <!-- rh_p12_rn_l1 -->
  <gazebo reference="rh_p12_rn_l1">
    <mu1>15</mu1>
    <mu2>150</mu2>
    <material>Gazebo/DarkGrey</material>
    <minDepth>0.001</minDepth>
    <maxVel>0</maxVel>
  </gazebo>
  <!-- rh_p12_rn_l2 -->
  <gazebo reference="rh_p12_rn_l2">
    <mu1>15</mu1>
    <mu2>150</mu2>
    <material>Gazebo/DarkGrey</material>
    <minDepth>0.001</minDepth>
    <maxVel>0</maxVel>
  </gazebo>
  <!-- Import Rviz colors -->
  <!-- <xacro:include filename="$(find husky_description)/urdf/decorations.urdf.xacro" /> -->
  <!-- base -->
  <link name="rh_p12_rn_base">
    <collision>
      <origin rpy="0 0 0" xyz="0 0 0"/>
      <geometry>
        <mesh filename="package://husky_description/meshes/base.stl" scale="0.001 0.001 0.001"/>
      </geometry>
    </collision>
    <visual>
      <origin rpy="0 0 0" xyz="0 0 0"/>
      <geometry>
        <mesh filename="package://husky_description/meshes/base.stl" scale="0.001 0.001 0.001"/>
      </geometry>
      <material name="grey"/>
    </visual>
    <inertial>
      <origin rpy="0 0 0" xyz="0.000 0.000 0.032"/>
      <mass value="0.236"/>
      <!--<inertia ixx="0.00017" ixy="0.0" ixz="0.0" iyy="0.00011" iyz="0.0" izz="0.00017" />-->
      <inertia ixx="1.0" ixy="0.0" ixz="0.0" iyy="1.0" iyz="0.0" izz="1.0"/>
    </inertial>
  </link>
  <!-- Joint -->
  <joint name="rh_p12_rn" type="revolute">
    <parent link="rh_p12_rn_base"/>
    <child link="rh_p12_rn_r1"/>
    <origin rpy="0 0 0" xyz="0.0 0.008 0.048"/>
    <axis xyz="1 0 0"/>
    <limit effort="1000" lower="0.0" upper="1.1" velocity="6.5"/>
    <dynamics damping="0.7"/>
  </joint>
  <transmission name="tran_r1">
    <type>transmission_interface/SimpleTransmission</type>
    <joint name="rh_p12_rn">
      <hardwareInterface>hardware_interface/EffortJointInterface</hardwareInterface>
    </joint>
    <actuator name="motor_r1">
      <hardwareInterface>hardware_interface/EffortJointInterface</hardwareInterface>
      <mechanicalReduction>1</mechanicalReduction>
    </actuator>
  </transmission>
  <!-- rh_p12_rn_r1 -->
  <link name="rh_p12_rn_r1">
    <collision>
      <origin rpy="0 0 0" xyz="0 0 0"/>
      <geometry>
        <mesh filename="package://husky_description/meshes/r1.stl" scale="0.001 0.001 0.001"/>
      </geometry>
    </collision>
    <visual>
      <origin rpy="0 0 0" xyz="0 0 0"/>
      <geometry>
        <mesh filename="package://husky_description/meshes/r1.stl" scale="0.001 0.001 0.001"/>
      </geometry>
      <material name="grey"/>
    </visual>
    <inertial>
      <origin rpy="0 0 0" xyz="0.000 0.034 0.004"/>
      <mass value="0.068"/>
      <!--<inertia ixx="0.00004" ixy="0.0" ixz="0.0" iyy="0.00002" iyz="-0.00001" izz="0.00002" />-->
      <inertia ixx="1.0" ixy="0.0" ixz="0.0" iyy="1.0" iyz="0.0" izz="1.0"/>
    </inertial>
  </link>
  <!-- Right Joint 2 -->
  <joint name="rh_r2" type="revolute">
    <parent link="rh_p12_rn_r1"/>
    <child link="rh_p12_rn_r2"/>
    <origin rpy="0 0 0" xyz="0.0 0.0493634 0.0285"/>
    <axis xyz="-1 0 0"/>
    <limit effort="1000" lower="0.0" upper="1.0" velocity="6.5"/>
    <dynamics damping="0.7"/>
  </joint>
  <transmission name="tran_r2">
    <type>transmission_interface/SimpleTransmission</type>
    <joint name="rh_r2">
      <hardwareInterface>hardware_interface/EffortJointInterface</hardwareInterface>
    </joint>
    <actuator name="motor_r2">
      <hardwareInterface>hardware_interface/EffortJointInterface</hardwareInterface>
      <mechanicalReduction>1</mechanicalReduction>
    </actuator>
  </transmission>
  <!-- rh_p12_rn_r2 -->
  <link name="rh_p12_rn_r2">
    <collision>
      <origin rpy="0 0 0" xyz="0 0 0"/>
      <geometry>
        <mesh filename="package://husky_description/meshes/r2.stl" scale="0.001 0.001 0.001"/>
      </geometry>
    </collision>
    <visual>
      <origin rpy="0 0 0" xyz="0 0 0"/>
      <geometry>
        <mesh filename="package://husky_description/meshes/r2.stl" scale="0.001 0.001 0.001"/>
      </geometry>
      <material name="grey"/>
    </visual>
    <inertial>
      <origin rpy="0 0 0" xyz="0.000 0.006 0.011"/>
      <mass value="0.022"/>
      <!--<inertia ixx="0.0" ixy="0.0" ixz="0.0" iyy="0.00001" iyz="0.0" izz="0.0" />-->
      <inertia ixx="1.0" ixy="0.0" ixz="0.0" iyy="1.0" iyz="0.0" izz="1.0"/>
    </inertial>
  </link>
  <!-- Left Joint 1 -->
  <joint name="rh_l1" type="revolute">
    <parent link="rh_p12_rn_base"/>
    <child link="rh_p12_rn_l1"/>
    <origin rpy="0 0 0" xyz="0.0 -0.008 0.048"/>
    <axis xyz="-1 0 0"/>
    <limit effort="1000" lower="0.0" upper="1.1" velocity="6.5"/>
    <dynamics damping="0.7"/>
  </joint>
  <transmission name="tran_l1">
    <type>transmission_interface/SimpleTransmission</type>
    <joint name="rh_l1">
      <hardwareInterface>hardware_interface/EffortJointInterface</hardwareInterface>
    </joint>
    <actuator name="motor_l1">
      <hardwareInterface>hardware_interface/EffortJointInterface</hardwareInterface>
      <mechanicalReduction>1</mechanicalReduction>
    </actuator>
  </transmission>
  <!-- rh_p12_rn_l1 -->
  <link name="rh_p12_rn_l1">
    <collision>
      <origin rpy="0 0 0" xyz="0 0 0"/>
      <geometry>
        <mesh filename="package://husky_description/meshes/l1.stl" scale="0.001 0.001 0.001"/>
      </geometry>
    </collision>
    <visual>
      <origin rpy="0 0 0" xyz="0 0 0"/>
      <geometry>
        <mesh filename="package://husky_description/meshes/l1.stl" scale="0.001 0.001 0.001"/>
      </geometry>
      <material name="grey"/>
    </visual>
    <inertial>
      <origin rpy="0 0 0" xyz="0.000 -0.034 0.004"/>
      <mass value="0.068"/>
      <!--<inertia ixx="0.00004" ixy="0.0" ixz="0.0" iyy="0.00002" iyz="0.00001" izz="0.00002" />-->
      <inertia ixx="1.0" ixy="0.0" ixz="0.0" iyy="1.0" iyz="0.0" izz="1.0"/>
    </inertial>
  </link>
  <!-- Left Joint 2 -->
  <joint name="rh_l2" type="revolute">
    <parent link="rh_p12_rn_l1"/>
    <child link="rh_p12_rn_l2"/>
    <origin rpy="0 0 0" xyz="0.0 -0.0493634 0.0285"/>
    <axis xyz="1 0 0"/>
    <limit effort="1000" lower="0.0" upper="1.0" velocity="6.5"/>
    <dynamics damping="0.7"/>
  </joint>
  <transmission name="tran_l2">
    <type>transmission_interface/SimpleTransmission</type>
    <joint name="rh_l2">
      <hardwareInterface>hardware_interface/EffortJointInterface</hardwareInterface>
    </joint>
    <actuator name="motor_l2">
      <hardwareInterface>hardware_interface/EffortJointInterface</hardwareInterface>
      <mechanicalReduction>1</mechanicalReduction>
    </actuator>
  </transmission>
  <!-- rh_p12_rn_l2 -->
  <link name="rh_p12_rn_l2">
    <collision>
      <origin rpy="0 0 0" xyz="0 0 0"/>
      <geometry>
        <mesh filename="package://husky_description/meshes/l2.stl" scale="0.001 0.001 0.001"/>
      </geometry>
    </collision>
    <visual>
      <origin rpy="0 0 0" xyz="0 0 0"/>
      <geometry>
        <mesh filename="package://husky_description/meshes/l2.stl" scale="0.001 0.001 0.001"/>
      </geometry>
      <material name="grey"/>
    </visual>
    <inertial>
      <origin rpy="0 0 0" xyz="0.000 -0.006 0.011"/>
      <mass value="0.022"/>
      <!--<inertia ixx="0.0" ixy="0.0" ixz="0.0" iyy="0.00001" iyz="0.0" izz="0.0" />-->
      <inertia ixx="1.0" ixy="0.0" ixz="0.0" iyy="1.0" iyz="0.0" izz="1.0"/>
    </inertial>
  </link>
  <!-- Mount link for the UR arm -->
  <link name="ur_mount_link">
    <visual>
      <geometry>
        <box size="0.1 0.1 0.05"/>
      </geometry>
      <material name="black"/>
    </visual>
    <collision>
      <geometry>
        <box size="0.1 0.1 0.05"/>
      </geometry>
    </collision>
    <inertial>
      <mass value="1.0"/>
      <inertia ixx="0.001" ixy="0.0" ixz="0.0" iyy="0.001" iyz="0.0" izz="0.001"/>
    </inertial>
  </link>
  <!-- Mount the UR arm base on top of Husky -->
  <joint name="ur_mount_joint" type="fixed">
    <parent link="top_plate_link"/>
    <child link="ur_mount_link"/>
    <origin rpy="0 0 0" xyz="0.0 0.0 -0.01"/>
  </joint>
  <ros2_control name="ur3" type="system">
    <hardware>
      <plugin>ur_robot_driver/URPositionHardwareInterface</plugin>
      <param name="robot_ip">0.0.0.0</param>
      <param name="script_filename">to_be_filled_by_ur_robot_driver</param>
      <param name="output_recipe_filename">to_be_filled_by_ur_robot_driver</param>
      <param name="input_recipe_filename">to_be_filled_by_ur_robot_driver</param>
      <param name="headless_mode">False</param>
      <param name="reverse_port">50001</param>
      <param name="script_sender_port">50002</param>
      <param name="reverse_ip">0.0.0.0</param>
      <param name="script_command_port">50004</param>
      <param name="trajectory_port">50003</param>
      <param name="tf_prefix">ur_</param>
      <param name="non_blocking_read">True</param>
      <param name="servoj_gain">2000</param>
      <param name="servoj_lookahead_time">0.03</param>
      <param name="use_tool_communication">False</param>
      <param name="kinematics/hash">calib_9122066269688285636</param>
      <param name="tool_voltage">0</param>
      <param name="tool_parity">0</param>
      <param name="tool_baud_rate">115200</param>
      <param name="tool_stop_bits">1</param>
      <param name="tool_rx_idle_chars">1.5</param>
      <param name="tool_tx_idle_chars">3.5</param>
      <param name="tool_device_name">/tmp/ttyUR</param>
      <param name="tool_tcp_port">54321</param>
      <param name="keep_alive_count">2</param>
    </hardware>
    <joint name="ur_shoulder_pan_joint">
      <command_interface name="position"/>
      <command_interface name="velocity"/>
      <state_interface name="position">
        <!-- initial position for the FakeSystem and simulation -->
        <param name="initial_value">0.0</param>
      </state_interface>
      <state_interface name="velocity"/>
      <state_interface name="effort"/>
    </joint>
    <joint name="ur_shoulder_lift_joint">
      <command_interface name="position"/>
      <command_interface name="velocity"/>
      <state_interface name="position">
        <!-- initial position for the FakeSystem and simulation -->
        <param name="initial_value">-1.57</param>
      </state_interface>
      <state_interface name="velocity"/>
      <state_interface name="effort"/>
    </joint>
    <joint name="ur_elbow_joint">
      <command_interface name="position"/>
      <command_interface name="velocity"/>
      <state_interface name="position">
        <!-- initial position for the FakeSystem and simulation -->
        <param name="initial_value">0.0</param>
      </state_interface>
      <state_interface name="velocity"/>
      <state_interface name="effort"/>
    </joint>
    <joint name="ur_wrist_1_joint">
      <command_interface name="position"/>
      <command_interface name="velocity"/>
      <state_interface name="position">
        <!-- initial position for the FakeSystem and simulation -->
        <param name="initial_value">-1.57</param>
      </state_interface>
      <state_interface name="velocity"/>
      <state_interface name="effort"/>
    </joint>
    <joint name="ur_wrist_2_joint">
      <command_interface name="position"/>
      <command_interface name="velocity"/>
      <state_interface name="position">
        <!-- initial position for the FakeSystem and simulation -->
        <param name="initial_value">0.0</param>
      </state_interface>
      <state_interface name="velocity"/>
      <state_interface name="effort"/>
    </joint>
    <joint name="ur_wrist_3_joint">
      <command_interface name="position"/>
      <command_interface name="velocity"/>
      <state_interface name="position">
        <!-- initial position for the FakeSystem and simulation -->
        <param name="initial_value">0.0</param>
      </state_interface>
      <state_interface name="velocity"/>
      <state_interface name="effort"/>
    </joint>
    <sensor name="ur_tcp_fts_sensor">
      <state_interface name="force.x"/>
      <state_interface name="force.y"/>
      <state_interface name="force.z"/>
      <state_interface name="torque.x"/>
      <state_interface name="torque.y"/>
      <state_interface name="torque.z"/>
    </sensor>
    <sensor name="ur_tcp_pose">
      <state_interface name="position.x"/>
      <state_interface name="position.y"/>
      <state_interface name="position.z"/>
      <state_interface name="orientation.x"/>
      <state_interface name="orientation.y"/>
      <state_interface name="orientation.z"/>
      <state_interface name="orientation.w"/>
    </sensor>
    <!-- NOTE The following are joints used only for testing with fake hardware and will change in the future -->
    <gpio name="ur_speed_scaling">
      <state_interface name="speed_scaling_factor"/>
      <param name="initial_speed_scaling_factor">1</param>
      <command_interface name="target_speed_fraction_cmd"/>
      <command_interface name="target_speed_fraction_async_success"/>
    </gpio>
    <gpio name="ur_gpio">
      <command_interface name="standard_digital_output_cmd_0"/>
      <command_interface name="standard_digital_output_cmd_1"/>
      <command_interface name="standard_digital_output_cmd_2"/>
      <command_interface name="standard_digital_output_cmd_3"/>
      <command_interface name="standard_digital_output_cmd_4"/>
      <command_interface name="standard_digital_output_cmd_5"/>
      <command_interface name="standard_digital_output_cmd_6"/>
      <command_interface name="standard_digital_output_cmd_7"/>
      <command_interface name="standard_digital_output_cmd_8"/>
      <command_interface name="standard_digital_output_cmd_9"/>
      <command_interface name="standard_digital_output_cmd_10"/>
      <command_interface name="standard_digital_output_cmd_11"/>
      <command_interface name="standard_digital_output_cmd_12"/>
      <command_interface name="standard_digital_output_cmd_13"/>
      <command_interface name="standard_digital_output_cmd_14"/>
      <command_interface name="standard_digital_output_cmd_15"/>
      <command_interface name="standard_digital_output_cmd_16"/>
      <command_interface name="standard_digital_output_cmd_17"/>
      <command_interface name="standard_analog_output_cmd_0"/>
      <command_interface name="standard_analog_output_cmd_1"/>
      <command_interface name="analog_output_domain_cmd"/>
      <command_interface name="tool_voltage_cmd"/>
      <command_interface name="io_async_success"/>
      <state_interface name="digital_output_0"/>
      <state_interface name="digital_output_1"/>
      <state_interface name="digital_output_2"/>
      <state_interface name="digital_output_3"/>
      <state_interface name="digital_output_4"/>
      <state_interface name="digital_output_5"/>
      <state_interface name="digital_output_6"/>
      <state_interface name="digital_output_7"/>
      <state_interface name="digital_output_8"/>
      <state_interface name="digital_output_9"/>
      <state_interface name="digital_output_10"/>
      <state_interface name="digital_output_11"/>
      <state_interface name="digital_output_12"/>
      <state_interface name="digital_output_13"/>
      <state_interface name="digital_output_14"/>
      <state_interface name="digital_output_15"/>
      <state_interface name="digital_output_16"/>
      <state_interface name="digital_output_17"/>
      <state_interface name="digital_input_0"/>
      <state_interface name="digital_input_1"/>
      <state_interface name="digital_input_2"/>
      <state_interface name="digital_input_3"/>
      <state_interface name="digital_input_4"/>
      <state_interface name="digital_input_5"/>
      <state_interface name="digital_input_6"/>
      <state_interface name="digital_input_7"/>
      <state_interface name="digital_input_8"/>
      <state_interface name="digital_input_9"/>
      <state_interface name="digital_input_10"/>
      <state_interface name="digital_input_11"/>
      <state_interface name="digital_input_12"/>
      <state_interface name="digital_input_13"/>
      <state_interface name="digital_input_14"/>
      <state_interface name="digital_input_15"/>
      <state_interface name="digital_input_16"/>
      <state_interface name="digital_input_17"/>
      <state_interface name="standard_analog_output_0"/>
      <state_interface name="standard_analog_output_1"/>
      <state_interface name="standard_analog_input_0"/>
      <state_interface name="standard_analog_input_1"/>
      <state_interface name="analog_io_type_0"/>
      <state_interface name="analog_io_type_1"/>
      <state_interface name="analog_io_type_2"/>
      <state_interface name="analog_io_type_3"/>
      <state_interface name="tool_mode"/>
      <state_interface name="tool_output_voltage"/>
      <state_interface name="tool_output_current"/>
      <state_interface name="tool_temperature"/>
      <state_interface name="tool_analog_input_0"/>
      <state_interface name="tool_analog_input_1"/>
      <state_interface name="tool_analog_input_type_0"/>
      <state_interface name="tool_analog_input_type_1"/>
      <state_interface name="robot_mode"/>
      <state_interface name="robot_status_bit_0"/>
      <state_interface name="robot_status_bit_1"/>
      <state_interface name="robot_status_bit_2"/>
      <state_interface name="robot_status_bit_3"/>
      <state_interface name="safety_mode"/>
      <state_interface name="safety_status_bit_0"/>
      <state_interface name="safety_status_bit_1"/>
      <state_interface name="safety_status_bit_2"/>
      <state_interface name="safety_status_bit_3"/>
      <state_interface name="safety_status_bit_4"/>
      <state_interface name="safety_status_bit_5"/>
      <state_interface name="safety_status_bit_6"/>
      <state_interface name="safety_status_bit_7"/>
      <state_interface name="safety_status_bit_8"/>
      <state_interface name="safety_status_bit_9"/>
      <state_interface name="safety_status_bit_10"/>
      <state_interface name="program_running"/>
    </gpio>
    <gpio name="ur_payload">
      <command_interface name="mass"/>
      <command_interface name="cog.x"/>
      <command_interface name="cog.y"/>
      <command_interface name="cog.z"/>
      <command_interface name="payload_async_success"/>
    </gpio>
    <gpio name="ur_resend_robot_program">
      <command_interface name="resend_robot_program_cmd"/>
      <command_interface name="resend_robot_program_async_success"/>
    </gpio>
    <gpio name="ur_hand_back_control">
      <command_interface name="hand_back_control_cmd"/>
      <command_interface name="hand_back_control_async_success"/>
    </gpio>
    <gpio name="ur_zero_ftsensor">
      <command_interface name="zero_ftsensor_cmd"/>
      <command_interface name="zero_ftsensor_async_success"/>
    </gpio>
    <gpio name="ur_freedrive_mode">
      <command_interface name="async_success"/>
      <command_interface name="enable"/>
      <command_interface name="abort"/>
    </gpio>
    <gpio name="ur_tool_contact">
      <command_interface name="tool_contact_set_state"/>
      <state_interface name="tool_contact_result"/>
      <state_interface name="tool_contact_state"/>
    </gpio>
    <gpio name="ur_system_interface">
      <state_interface name="initialized"/>
    </gpio>
    <gpio name="ur_force_mode">
      <command_interface name="task_frame_x"/>
      <command_interface name="task_frame_y"/>
      <command_interface name="task_frame_z"/>
      <command_interface name="task_frame_rx"/>
      <command_interface name="task_frame_ry"/>
      <command_interface name="task_frame_rz"/>
      <command_interface name="selection_vector_x"/>
      <command_interface name="selection_vector_y"/>
      <command_interface name="selection_vector_z"/>
      <command_interface name="selection_vector_rx"/>
      <command_interface name="selection_vector_ry"/>
      <command_interface name="selection_vector_rz"/>
      <command_interface name="wrench_x"/>
      <command_interface name="wrench_y"/>
      <command_interface name="wrench_z"/>
      <command_interface name="wrench_rx"/>
      <command_interface name="wrench_ry"/>
      <command_interface name="wrench_rz"/>
      <command_interface name="limits_x"/>
      <command_interface name="limits_y"/>
      <command_interface name="limits_z"/>
      <command_interface name="limits_rx"/>
      <command_interface name="limits_ry"/>
      <command_interface name="limits_rz"/>
      <command_interface name="type"/>
      <command_interface name="damping"/>
      <command_interface name="gain_scaling"/>
      <command_interface name="disable_cmd"/>
      <command_interface name="force_mode_async_success"/>
    </gpio>
    <gpio name="ur_trajectory_passthrough">
      <command_interface name="setpoint_positions_0"/>
      <command_interface name="setpoint_positions_1"/>
      <command_interface name="setpoint_positions_2"/>
      <command_interface name="setpoint_positions_3"/>
      <command_interface name="setpoint_positions_4"/>
      <command_interface name="setpoint_positions_5"/>
      <command_interface name="setpoint_velocities_0"/>
      <command_interface name="setpoint_velocities_1"/>
      <command_interface name="setpoint_velocities_2"/>
      <command_interface name="setpoint_velocities_3"/>
      <command_interface name="setpoint_velocities_4"/>
      <command_interface name="setpoint_velocities_5"/>
      <command_interface name="setpoint_accelerations_0"/>
      <command_interface name="setpoint_accelerations_1"/>
      <command_interface name="setpoint_accelerations_2"/>
      <command_interface name="setpoint_accelerations_3"/>
      <command_interface name="setpoint_accelerations_4"/>
      <command_interface name="setpoint_accelerations_5"/>
      <command_interface name="transfer_state"/>
      <command_interface name="time_from_start"/>
      <command_interface name="abort"/>
    </gpio>
    <gpio name="ur_get_robot_software_version">
      <state_interface name="get_version_major">
        <param name="initial_value">1</param>
      </state_interface>
      <state_interface name="get_version_minor"/>
      <state_interface name="get_version_build"/>
      <state_interface name="get_version_bugfix"/>
    </gpio>
  </ros2_control>
  <!-- Add URDF transmission elements (for ros_control) -->
  <!--<xacro:ur_arm_transmission prefix="${prefix}" hw_interface="${transmission_hw_interface}" />-->
  <!-- Placeholder for ros2_control transmission which don't yet exist -->
  <!-- links -  main serial chain -->
  <link name="ur_base_link"/>
  <link name="ur_base_link_inertia">
    <visual>
      <origin rpy="0 0 3.141592653589793" xyz="0 0 0"/>
      <geometry>
        <mesh filename="package://ur_description/meshes/ur3/visual/base.dae"/>
      </geometry>
    </visual>
    <collision>
      <origin rpy="0 0 3.141592653589793" xyz="0 0 0"/>
      <geometry>
        <mesh filename="package://ur_description/meshes/ur3/collision/base.stl"/>
      </geometry>
    </collision>
    <inertial>
      <mass value="2.0"/>
      <origin rpy="0 0 0" xyz="0 0 0"/>
      <inertia ixx="0.0030531654454" ixy="0.0" ixz="0.0" iyy="0.0030531654454" iyz="0.0" izz="0.005625"/>
    </inertial>
  </link>
  <link name="ur_shoulder_link">
    <visual>
      <origin rpy="0 0 3.141592653589793" xyz="0 0 0"/>
      <geometry>
        <mesh filename="package://ur_description/meshes/ur3/visual/shoulder.dae"/>
      </geometry>
    </visual>
    <collision>
      <origin rpy="0 0 3.141592653589793" xyz="0 0 0"/>
      <geometry>
        <mesh filename="package://ur_description/meshes/ur3/collision/shoulder.stl"/>
      </geometry>
    </collision>
    <inertial>
      <mass value="2.0"/>
      <origin rpy="0 0 0" xyz="0.0 0.0 -0.02"/>
      <inertia ixx="0.008093166666666665" ixy="0" ixz="0" iyy="0.008093166666666665" iyz="0" izz="0.005625"/>
    </inertial>
  </link>
  <link name="ur_upper_arm_link">
    <visual>
      <origin rpy="1.5707963267948966 0 -1.5707963267948966" xyz="0 0 0.1198"/>
      <geometry>
        <mesh filename="package://ur_description/meshes/ur3/visual/upperarm.dae"/>
      </geometry>
    </visual>
    <collision>
      <origin rpy="1.5707963267948966 0 -1.5707963267948966" xyz="0 0 0.1198"/>
      <geometry>
        <mesh filename="package://ur_description/meshes/ur3/collision/upperarm.stl"/>
      </geometry>
    </collision>
    <inertial>
      <mass value="3.42"/>
      <origin rpy="0 1.570796326794897 0" xyz="-0.11365 0.0 0.1157"/>
      <inertia ixx="0.021728491912499998" ixy="0" ixz="0" iyy="0.021728491912499998" iyz="0" izz="0.00961875"/>
    </inertial>
  </link>
  <link name="ur_forearm_link">
    <visual>
      <origin rpy="1.5707963267948966 0 -1.5707963267948966" xyz="0 0 0.0275"/>
      <geometry>
        <mesh filename="package://ur_description/meshes/ur3/visual/forearm.dae"/>
      </geometry>
    </visual>
    <collision>
      <origin rpy="1.5707963267948966 0 -1.5707963267948966" xyz="0 0 0.0275"/>
      <geometry>
        <mesh filename="package://ur_description/meshes/ur3/collision/forearm.stl"/>
      </geometry>
    </collision>
    <inertial>
      <mass value="1.26"/>
      <origin rpy="0 1.570796326794897 0" xyz="-0.16325 0.0 0.0238"/>
      <inertia ixx="0.0065468090625" ixy="0" ixz="0" iyy="0.0065468090625" iyz="0" izz="0.00354375"/>
    </inertial>
  </link>
  <link name="ur_wrist_1_link">
    <visual>
      <origin rpy="1.5707963267948966 0 0" xyz="0 0 -0.085"/>
      <geometry>
        <mesh filename="package://ur_description/meshes/ur3/visual/wrist1.dae"/>
      </geometry>
    </visual>
    <collision>
      <origin rpy="1.5707963267948966 0 0" xyz="0 0 -0.085"/>
      <geometry>
        <mesh filename="package://ur_description/meshes/ur3/collision/wrist1.stl"/>
      </geometry>
    </collision>
    <inertial>
      <mass value="0.8"/>
      <origin rpy="0 0 0" xyz="0.0 -0.01 0.0"/>
      <inertia ixx="0.0016106414999999998" ixy="0" ixz="0" iyy="0.0016106414999999998" iyz="0" izz="0.00225"/>
    </inertial>
  </link>
  <link name="ur_wrist_2_link">
    <visual>
      <origin rpy="0 0 0" xyz="0 0 -0.083"/>
      <geometry>
        <mesh filename="package://ur_description/meshes/ur3/visual/wrist2.dae"/>
      </geometry>
    </visual>
    <collision>
      <origin rpy="0 0 0" xyz="0 0 -0.083"/>
      <geometry>
        <mesh filename="package://ur_description/meshes/ur3/collision/wrist2.stl"/>
      </geometry>
    </collision>
    <inertial>
      <mass value="0.8"/>
      <origin rpy="0 0 0" xyz="0.0 0.01 0.0"/>
      <inertia ixx="0.0015721739999999998" ixy="0" ixz="0" iyy="0.0015721739999999998" iyz="0" izz="0.00225"/>
    </inertial>
  </link>
  <link name="ur_wrist_3_link">
    <visual>
      <origin rpy="1.5707963267948966 0 0" xyz="0 -0.00255 -0.082"/>
      <geometry>
        <mesh filename="package://ur_description/meshes/ur3/visual/wrist3.dae"/>
      </geometry>
    </visual>
    <collision>
      <origin rpy="1.5707963267948966 0 0" xyz="0 -0.00255 -0.082"/>
      <geometry>
        <mesh filename="package://ur_description/meshes/ur3/collision/wrist3.stl"/>
      </geometry>
    </collision>
    <inertial>
      <mass value="0.35"/>
      <origin rpy="0 0 0" xyz="0.0 0.0 -0.02"/>
      <inertia ixx="0.00013626666666666665" ixy="0" ixz="0" iyy="0.00013626666666666665" iyz="0" izz="0.0001792"/>
    </inertial>
  </link>
  <!-- base_joint fixes base_link to the environment -->
  <joint name="ur_base_joint" type="fixed">
    <origin rpy="0 0 0" xyz="0 0 0.05"/>
    <parent link="ur_mount_link"/>
    <child link="ur_base_link"/>
  </joint>
  <!-- joints - main serial chain -->
  <joint name="ur_base_link-base_link_inertia" type="fixed">
    <parent link="ur_base_link"/>
    <child link="ur_base_link_inertia"/>
    <!-- 'base_link' is REP-103 aligned (so X+ forward), while the internal
           frames of the robot/controller have X+ pointing backwards.
           Use the joint between 'base_link' and 'base_link_inertia' (a dummy
           link/frame) to introduce the necessary rotation over Z (of pi rad).
      -->
    <origin rpy="0 0 3.141592653589793" xyz="0 0 0"/>
  </joint>
  <joint name="ur_shoulder_pan_joint" type="revolute">
    <parent link="ur_base_link_inertia"/>
    <child link="ur_shoulder_link"/>
    <origin rpy="0 0 0" xyz="0 0 0.1519"/>
    <axis xyz="0 0 1"/>
    <limit effort="56.0" lower="-6.283185307179586" upper="6.283185307179586" velocity="3.141592653589793"/>
    <dynamics damping="0" friction="0"/>
  </joint>
  <joint name="ur_shoulder_lift_joint" type="revolute">
    <parent link="ur_shoulder_link"/>
    <child link="ur_upper_arm_link"/>
    <origin rpy="1.570796327 0 0" xyz="0 0 0"/>
    <axis xyz="0 0 1"/>
    <limit effort="56.0" lower="-6.283185307179586" upper="6.283185307179586" velocity="3.141592653589793"/>
    <dynamics damping="0" friction="0"/>
  </joint>
  <joint name="ur_elbow_joint" type="revolute">
    <parent link="ur_upper_arm_link"/>
    <child link="ur_forearm_link"/>
    <origin rpy="0 0 0" xyz="-0.24365 0 0"/>
    <axis xyz="0 0 1"/>
    <limit effort="28.0" lower="-3.141592653589793" upper="3.141592653589793" velocity="3.141592653589793"/>
    <dynamics damping="0" friction="0"/>
  </joint>
  <joint name="ur_wrist_1_joint" type="revolute">
    <parent link="ur_forearm_link"/>
    <child link="ur_wrist_1_link"/>
    <origin rpy="0 0 0" xyz="-0.21325 0 0.11235"/>
    <axis xyz="0 0 1"/>
    <limit effort="12.0" lower="-6.283185307179586" upper="6.283185307179586" velocity="6.283185307179586"/>
    <dynamics damping="0" friction="0"/>
  </joint>
  <joint name="ur_wrist_2_joint" type="revolute">
    <parent link="ur_wrist_1_link"/>
    <child link="ur_wrist_2_link"/>
    <origin rpy="1.570796327 0 0" xyz="0 -0.08535 -1.750557762378351e-11"/>
    <axis xyz="0 0 1"/>
    <limit effort="12.0" lower="-6.283185307179586" upper="6.283185307179586" velocity="6.283185307179586"/>
    <dynamics damping="0" friction="0"/>
  </joint>
  <joint name="ur_wrist_3_joint" type="continuous">
    <parent link="ur_wrist_2_link"/>
    <child link="ur_wrist_3_link"/>
    <origin rpy="1.570796326589793 3.141592653589793 3.141592653589793" xyz="0 0.0819 -1.679797079540562e-11"/>
    <axis xyz="0 0 1"/>
    <limit effort="12.0" velocity="6.283185307179586"/>
    <dynamics damping="0" friction="0"/>
  </joint>
  <link name="ur_ft_frame"/>
  <joint name="ur_wrist_3_link-ft_frame" type="fixed">
    <parent link="ur_wrist_3_link"/>
    <child link="ur_ft_frame"/>
    <origin rpy="3.141592653589793 0 0" xyz="0 0 0"/>
  </joint>
  <!-- ROS-Industrial 'base' frame - base_link to UR 'Base' Coordinates transform -->
  <link name="ur_base"/>
  <joint name="ur_base_link-base_fixed_joint" type="fixed">
    <!-- Note the rotation over Z of pi radians - as base_link is REP-103
           aligned (i.e., has X+ forward, Y+ left and Z+ up), this is needed
           to correctly align 'base' with the 'Base' coordinate system of
           the UR controller.
      -->
    <origin rpy="0 0 3.141592653589793" xyz="0 0 0"/>
    <parent link="ur_base_link"/>
    <child link="ur_base"/>
  </joint>
  <!-- ROS-Industrial 'flange' frame - attachment point for EEF models -->
  <link name="ur_flange"/>
  <joint name="ur_wrist_3-flange" type="fixed">
    <parent link="ur_wrist_3_link"/>
    <child link="ur_flange"/>
    <origin rpy="0 -1.5707963267948966 -1.5707963267948966" xyz="0 0 0"/>
  </joint>
  <!-- ROS-Industrial 'tool0' frame - all-zeros tool frame -->
  <link name="ur_tool0"/>
  <joint name="ur_flange-tool0" type="fixed">
    <!-- default toolframe - X+ left, Y+ up, Z+ front -->
    <origin rpy="1.5707963267948966 0 1.5707963267948966" xyz="0 0 0"/>
    <parent link="ur_flange"/>
    <child link="ur_tool0"/>
  </joint>
  <!-- Attach gripper to UR3 tool0 -->
  <joint name="gripper_mount_joint" type="fixed">
    <parent link="ur_tool0"/>
    <child link="rh_p12_rn_base"/>
    <origin rpy="0 1.57 0" xyz="0 0 0"/>
  </joint>
  <!-- ros2_control for UR3 in simulation -->
  <ros2_control name="ur_hardware" type="system">
    <hardware>
      <plugin>ign_ros2_control/IgnitionSystem</plugin>
    </hardware>
    <joint name="ur_shoulder_pan_joint">
      <command_interface name="position">
        <param name="min">-6.28</param>
        <param name="max">6.28</param>
      </command_interface>
      <state_interface name="position"/>
      <state_interface name="velocity"/>
    </joint>
    <joint name="ur_shoulder_lift_joint">
      <command_interface name="position">
        <param name="min">-6.28</param>
        <param name="max">6.28</param>
      </command_interface>
      <state_interface name="position"/>
      <state_interface name="velocity"/>
    </joint>
    <joint name="ur_elbow_joint">
      <command_interface name="position">
        <param name="min">-3.14</param>
        <param name="max">3.14</param>
      </command_interface>
      <state_interface name="position"/>
      <state_interface name="velocity"/>
    </joint>
    <joint name="ur_wrist_1_joint">
      <command_interface name="position">
        <param name="min">-6.28</param>
        <param name="max">6.28</param>
      </command_interface>
      <state_interface name="position"/>
      <state_interface name="velocity"/>
    </joint>
    <joint name="ur_wrist_2_joint">
      <command_interface name="position">
        <param name="min">-6.28</param>
        <param name="max">6.28</param>
      </command_interface>
      <state_interface name="position"/>
      <state_interface name="velocity"/>
    </joint>
    <joint name="ur_wrist_3_joint">
      <command_interface name="position">
        <param name="min">-6.28</param>
        <param name="max">6.28</param>
      </command_interface>
      <state_interface name="position"/>
      <state_interface name="velocity"/>
    </joint>
  </ros2_control>
  <!-- ros2_control for Robotis Gripper
  <ros2_control name="robotis_gripper_hardware" type="system">
    <hardware>
      <xacro:if value="$(arg is_sim)">
        <plugin>ign_ros2_control/IgnitionSystem</plugin>
      </xacro:if>
      <xacro:unless value="$(arg is_sim)">
        <plugin>robotis_hardware_interface/RobotisPositionHardwareInterface</plugin>
      </xacro:unless>
    </hardware>
    
    <joint name="robotis_left_finger_joint">
      <command_interface name="position">
        <param name="min">0.0</param>
        <param name="max">0.04</param>
      </command_interface>
      <state_interface name="position"/>
      <state_interface name="velocity"/>
    </joint>
  </ros2_control> -->
  <gazebo>
    <plugin filename="libign_ros2_control-system.so" name="ign_ros2_control::IgnitionROS2ControlPlugin">
      <parameters>/home/rinav/ros2_ws/src/husky/husky_control/config/control.yaml</parameters>
    </plugin>
  </gazebo>
  <!-- IMU -->
  <gazebo reference="imu_link">
    <sensor name="imu_sensor" type="imu">
      <always_on>true</always_on>
      <update_rate>100</update_rate>
      <visualize>true</visualize>
      <topic>imu/data_raw</topic>
      <plugin filename="libignition-gazebo-imu-system.so" name="ignition::gazebo::systems::Imu">
        </plugin>
    </sensor>
  </gazebo>
  <!-- GPS -->
  <gazebo reference="gps_link">
    <sensor name="gps_sensor" type="navsat">
      <always_on>true</always_on>
      <update_rate>10</update_rate>
      <topic>gps/data</topic>
      <plugin filename="libignition-gazebo-navsat-system.so" name="ignition::gazebo::systems::NavSat">
        </plugin>
    </sensor>
  </gazebo>
  <!-- Gripper Gazebo properties -->
  <gazebo reference="robotis_left_finger_link">
    <material>Gazebo/Grey</material>
    <mu1>1.0</mu1>
    <mu2>1.0</mu2>
  </gazebo>
  <gazebo reference="robotis_right_finger_link">
    <material>Gazebo/Grey</material>
    <mu1>1.0</mu1>
    <mu2>1.0</mu2>
  </gazebo>
  <!-- This file is a placeholder which is included by default from
       husky.urdf.xacro. If a robot is being customized and requires
       additional URDF, set the HUSKY_URDF_EXTRAS environment variable
       to the full path of the file you would like included. -->
</robot>
